[2025-04-22T18:03:03.460+0000] {taskinstance.py:1157} INFO - Dependencies all met for dep_context=non-requeueable deps ti=<TaskInstance: user_etl_dag.load_users_to_postgres_db manual__2025-04-22T18:02:38.072280+00:00 [queued]>
[2025-04-22T18:03:03.500+0000] {taskinstance.py:1157} INFO - Dependencies all met for dep_context=requeueable deps ti=<TaskInstance: user_etl_dag.load_users_to_postgres_db manual__2025-04-22T18:02:38.072280+00:00 [queued]>
[2025-04-22T18:03:03.502+0000] {taskinstance.py:1359} INFO - Starting attempt 1 of 2
[2025-04-22T18:03:03.666+0000] {taskinstance.py:1380} INFO - Executing <Task(PythonOperator): load_users_to_postgres_db> on 2025-04-22 18:02:38.072280+00:00
[2025-04-22T18:03:03.678+0000] {standard_task_runner.py:57} INFO - Started process 639 to run task
[2025-04-22T18:03:03.686+0000] {standard_task_runner.py:84} INFO - Running: ['airflow', 'tasks', 'run', 'user_etl_dag', 'load_users_to_postgres_db', 'manual__2025-04-22T18:02:38.072280+00:00', '--job-id', '17', '--raw', '--subdir', 'DAGS_FOLDER/user_et_dag.py', '--cfg-path', '/tmp/tmph65a4qs5']
[2025-04-22T18:03:03.689+0000] {standard_task_runner.py:85} INFO - Job 17: Subtask load_users_to_postgres_db
[2025-04-22T18:03:03.879+0000] {task_command.py:415} INFO - Running <TaskInstance: user_etl_dag.load_users_to_postgres_db manual__2025-04-22T18:02:38.072280+00:00 [running]> on host b5bb6c03d6dd
[2025-04-22T18:03:04.125+0000] {taskinstance.py:1660} INFO - Exporting env vars: AIRFLOW_CTX_DAG_OWNER='airflow' AIRFLOW_CTX_DAG_ID='user_etl_dag' AIRFLOW_CTX_TASK_ID='load_users_to_postgres_db' AIRFLOW_CTX_EXECUTION_DATE='2025-04-22T18:02:38.072280+00:00' AIRFLOW_CTX_TRY_NUMBER='1' AIRFLOW_CTX_DAG_RUN_ID='manual__2025-04-22T18:02:38.072280+00:00'
[2025-04-22T18:03:22.561+0000] {taskinstance.py:1935} ERROR - Task failed with exception
Traceback (most recent call last):
  File "/home/airflow/.local/lib/python3.8/site-packages/airflow/operators/python.py", line 192, in execute
    return_value = self.execute_callable()
  File "/home/airflow/.local/lib/python3.8/site-packages/airflow/operators/python.py", line 209, in execute_callable
    return self.python_callable(*self.op_args, **self.op_kwargs)
  File "/opt/airflow/dags/user_et_dag.py", line 27, in load_users
    conn = psycopg2.connect(
  File "/home/airflow/.local/lib/python3.8/site-packages/psycopg2/__init__.py", line 122, in connect
    conn = _connect(dsn, connection_factory=connection_factory, **kwasync)
psycopg2.OperationalError: connection to server on socket "/var/run/postgresql/.s.PGSQL.5433" failed: No such file or directory
	Is the server running locally and accepting connections on that socket?

[2025-04-22T18:03:22.595+0000] {taskinstance.py:1398} INFO - Marking task as UP_FOR_RETRY. dag_id=user_etl_dag, task_id=load_users_to_postgres_db, execution_date=20250422T180238, start_date=20250422T180303, end_date=20250422T180322
[2025-04-22T18:03:22.635+0000] {standard_task_runner.py:104} ERROR - Failed to execute job 17 for task load_users_to_postgres_db (connection to server on socket "/var/run/postgresql/.s.PGSQL.5433" failed: No such file or directory
	Is the server running locally and accepting connections on that socket?
; 639)
[2025-04-22T18:03:22.709+0000] {local_task_job_runner.py:228} INFO - Task exited with return code 1
[2025-04-22T18:03:22.831+0000] {taskinstance.py:2776} INFO - 0 downstream tasks scheduled from follow-on schedule check
