[2025-04-22T18:27:09.270+0000] {taskinstance.py:1157} INFO - Dependencies all met for dep_context=non-requeueable deps ti=<TaskInstance: user_etl_dag.load_users_to_postgres_db manual__2025-04-22T18:21:25.468273+00:00 [queued]>
[2025-04-22T18:27:09.295+0000] {taskinstance.py:1157} INFO - Dependencies all met for dep_context=requeueable deps ti=<TaskInstance: user_etl_dag.load_users_to_postgres_db manual__2025-04-22T18:21:25.468273+00:00 [queued]>
[2025-04-22T18:27:09.298+0000] {taskinstance.py:1359} INFO - Starting attempt 2 of 2
[2025-04-22T18:27:09.333+0000] {taskinstance.py:1380} INFO - Executing <Task(PythonOperator): load_users_to_postgres_db> on 2025-04-22 18:21:25.468273+00:00
[2025-04-22T18:27:09.349+0000] {standard_task_runner.py:57} INFO - Started process 1038 to run task
[2025-04-22T18:27:09.360+0000] {standard_task_runner.py:84} INFO - Running: ['airflow', 'tasks', 'run', 'user_etl_dag', 'load_users_to_postgres_db', 'manual__2025-04-22T18:21:25.468273+00:00', '--job-id', '24', '--raw', '--subdir', 'DAGS_FOLDER/user_et_dag.py', '--cfg-path', '/tmp/tmpt4xcymgz']
[2025-04-22T18:27:09.366+0000] {standard_task_runner.py:85} INFO - Job 24: Subtask load_users_to_postgres_db
[2025-04-22T18:27:09.520+0000] {task_command.py:415} INFO - Running <TaskInstance: user_etl_dag.load_users_to_postgres_db manual__2025-04-22T18:21:25.468273+00:00 [running]> on host b5bb6c03d6dd
[2025-04-22T18:27:09.777+0000] {taskinstance.py:1660} INFO - Exporting env vars: AIRFLOW_CTX_DAG_OWNER='airflow' AIRFLOW_CTX_DAG_ID='user_etl_dag' AIRFLOW_CTX_TASK_ID='load_users_to_postgres_db' AIRFLOW_CTX_EXECUTION_DATE='2025-04-22T18:21:25.468273+00:00' AIRFLOW_CTX_TRY_NUMBER='2' AIRFLOW_CTX_DAG_RUN_ID='manual__2025-04-22T18:21:25.468273+00:00'
[2025-04-22T18:27:29.621+0000] {logging_mixin.py:151} INFO - Used host: db
[2025-04-22T18:27:29.627+0000] {logging_mixin.py:151} INFO - Used port: 5433
[2025-04-22T18:27:29.631+0000] {taskinstance.py:1935} ERROR - Task failed with exception
Traceback (most recent call last):
  File "/home/airflow/.local/lib/python3.8/site-packages/airflow/operators/python.py", line 192, in execute
    return_value = self.execute_callable()
  File "/home/airflow/.local/lib/python3.8/site-packages/airflow/operators/python.py", line 209, in execute_callable
    return self.python_callable(*self.op_args, **self.op_kwargs)
  File "/opt/airflow/dags/user_et_dag.py", line 29, in load_users
    conn = psycopg2.connect(
  File "/home/airflow/.local/lib/python3.8/site-packages/psycopg2/__init__.py", line 122, in connect
    conn = _connect(dsn, connection_factory=connection_factory, **kwasync)
psycopg2.OperationalError: connection to server at "db" (172.28.0.3), port 5433 failed: Connection refused
	Is the server running on that host and accepting TCP/IP connections?

[2025-04-22T18:27:29.653+0000] {taskinstance.py:1398} INFO - Marking task as FAILED. dag_id=user_etl_dag, task_id=load_users_to_postgres_db, execution_date=20250422T182125, start_date=20250422T182709, end_date=20250422T182729
[2025-04-22T18:27:29.677+0000] {standard_task_runner.py:104} ERROR - Failed to execute job 24 for task load_users_to_postgres_db (connection to server at "db" (172.28.0.3), port 5433 failed: Connection refused
	Is the server running on that host and accepting TCP/IP connections?
; 1038)
[2025-04-22T18:27:29.730+0000] {local_task_job_runner.py:228} INFO - Task exited with return code 1
[2025-04-22T18:27:29.782+0000] {taskinstance.py:2776} INFO - 0 downstream tasks scheduled from follow-on schedule check
