[2025-04-22T18:00:39.976+0000] {taskinstance.py:1157} INFO - Dependencies all met for dep_context=non-requeueable deps ti=<TaskInstance: user_etl_dag.load_users_to_postgres_db manual__2025-04-22T18:00:07.989501+00:00 [queued]>
[2025-04-22T18:00:39.992+0000] {taskinstance.py:1157} INFO - Dependencies all met for dep_context=requeueable deps ti=<TaskInstance: user_etl_dag.load_users_to_postgres_db manual__2025-04-22T18:00:07.989501+00:00 [queued]>
[2025-04-22T18:00:39.993+0000] {taskinstance.py:1359} INFO - Starting attempt 1 of 2
[2025-04-22T18:00:40.014+0000] {taskinstance.py:1380} INFO - Executing <Task(PythonOperator): load_users_to_postgres_db> on 2025-04-22 18:00:07.989501+00:00
[2025-04-22T18:00:40.026+0000] {standard_task_runner.py:57} INFO - Started process 596 to run task
[2025-04-22T18:00:40.033+0000] {standard_task_runner.py:84} INFO - Running: ['airflow', 'tasks', 'run', 'user_etl_dag', 'load_users_to_postgres_db', 'manual__2025-04-22T18:00:07.989501+00:00', '--job-id', '15', '--raw', '--subdir', 'DAGS_FOLDER/user_et_dag.py', '--cfg-path', '/tmp/tmpikuzpiyi']
[2025-04-22T18:00:40.035+0000] {standard_task_runner.py:85} INFO - Job 15: Subtask load_users_to_postgres_db
[2025-04-22T18:00:40.136+0000] {task_command.py:415} INFO - Running <TaskInstance: user_etl_dag.load_users_to_postgres_db manual__2025-04-22T18:00:07.989501+00:00 [running]> on host b5bb6c03d6dd
[2025-04-22T18:00:40.285+0000] {taskinstance.py:1660} INFO - Exporting env vars: AIRFLOW_CTX_DAG_OWNER='airflow' AIRFLOW_CTX_DAG_ID='user_etl_dag' AIRFLOW_CTX_TASK_ID='load_users_to_postgres_db' AIRFLOW_CTX_EXECUTION_DATE='2025-04-22T18:00:07.989501+00:00' AIRFLOW_CTX_TRY_NUMBER='1' AIRFLOW_CTX_DAG_RUN_ID='manual__2025-04-22T18:00:07.989501+00:00'
[2025-04-22T18:01:02.056+0000] {taskinstance.py:1935} ERROR - Task failed with exception
Traceback (most recent call last):
  File "/home/airflow/.local/lib/python3.8/site-packages/airflow/operators/python.py", line 192, in execute
    return_value = self.execute_callable()
  File "/home/airflow/.local/lib/python3.8/site-packages/airflow/operators/python.py", line 209, in execute_callable
    return self.python_callable(*self.op_args, **self.op_kwargs)
  File "/opt/airflow/dags/user_et_dag.py", line 27, in load_users
    conn = psycopg2.connect(
  File "/home/airflow/.local/lib/python3.8/site-packages/psycopg2/__init__.py", line 122, in connect
    conn = _connect(dsn, connection_factory=connection_factory, **kwasync)
psycopg2.OperationalError: connection to server at "db" (172.28.0.3), port 5433 failed: Connection refused
	Is the server running on that host and accepting TCP/IP connections?

[2025-04-22T18:01:02.079+0000] {taskinstance.py:1398} INFO - Marking task as UP_FOR_RETRY. dag_id=user_etl_dag, task_id=load_users_to_postgres_db, execution_date=20250422T180007, start_date=20250422T180039, end_date=20250422T180102
[2025-04-22T18:01:02.099+0000] {standard_task_runner.py:104} ERROR - Failed to execute job 15 for task load_users_to_postgres_db (connection to server at "db" (172.28.0.3), port 5433 failed: Connection refused
	Is the server running on that host and accepting TCP/IP connections?
; 596)
[2025-04-22T18:01:02.147+0000] {local_task_job_runner.py:228} INFO - Task exited with return code 1
[2025-04-22T18:01:02.185+0000] {taskinstance.py:2776} INFO - 0 downstream tasks scheduled from follow-on schedule check
