[2025-04-22T18:06:03.888+0000] {taskinstance.py:1157} INFO - Dependencies all met for dep_context=non-requeueable deps ti=<TaskInstance: user_etl_dag.load_users_to_postgres_db manual__2025-04-22T18:00:07.989501+00:00 [queued]>
[2025-04-22T18:06:03.910+0000] {taskinstance.py:1157} INFO - Dependencies all met for dep_context=requeueable deps ti=<TaskInstance: user_etl_dag.load_users_to_postgres_db manual__2025-04-22T18:00:07.989501+00:00 [queued]>
[2025-04-22T18:06:03.912+0000] {taskinstance.py:1359} INFO - Starting attempt 2 of 2
[2025-04-22T18:06:03.949+0000] {taskinstance.py:1380} INFO - Executing <Task(PythonOperator): load_users_to_postgres_db> on 2025-04-22 18:00:07.989501+00:00
[2025-04-22T18:06:03.960+0000] {standard_task_runner.py:57} INFO - Started process 696 to run task
[2025-04-22T18:06:03.971+0000] {standard_task_runner.py:84} INFO - Running: ['airflow', 'tasks', 'run', 'user_etl_dag', 'load_users_to_postgres_db', 'manual__2025-04-22T18:00:07.989501+00:00', '--job-id', '18', '--raw', '--subdir', 'DAGS_FOLDER/user_et_dag.py', '--cfg-path', '/tmp/tmpu8qwphtw']
[2025-04-22T18:06:03.978+0000] {standard_task_runner.py:85} INFO - Job 18: Subtask load_users_to_postgres_db
[2025-04-22T18:06:04.145+0000] {task_command.py:415} INFO - Running <TaskInstance: user_etl_dag.load_users_to_postgres_db manual__2025-04-22T18:00:07.989501+00:00 [running]> on host b5bb6c03d6dd
[2025-04-22T18:06:04.397+0000] {taskinstance.py:1660} INFO - Exporting env vars: AIRFLOW_CTX_DAG_OWNER='airflow' AIRFLOW_CTX_DAG_ID='user_etl_dag' AIRFLOW_CTX_TASK_ID='load_users_to_postgres_db' AIRFLOW_CTX_EXECUTION_DATE='2025-04-22T18:00:07.989501+00:00' AIRFLOW_CTX_TRY_NUMBER='2' AIRFLOW_CTX_DAG_RUN_ID='manual__2025-04-22T18:00:07.989501+00:00'
[2025-04-22T18:06:23.746+0000] {taskinstance.py:1935} ERROR - Task failed with exception
Traceback (most recent call last):
  File "/home/airflow/.local/lib/python3.8/site-packages/airflow/operators/python.py", line 192, in execute
    return_value = self.execute_callable()
  File "/home/airflow/.local/lib/python3.8/site-packages/airflow/operators/python.py", line 209, in execute_callable
    return self.python_callable(*self.op_args, **self.op_kwargs)
  File "/opt/airflow/dags/user_et_dag.py", line 27, in load_users
    conn = psycopg2.connect(
  File "/home/airflow/.local/lib/python3.8/site-packages/psycopg2/__init__.py", line 122, in connect
    conn = _connect(dsn, connection_factory=connection_factory, **kwasync)
psycopg2.OperationalError: connection to server on socket "/var/run/postgresql/.s.PGSQL.5433" failed: No such file or directory
	Is the server running locally and accepting connections on that socket?

[2025-04-22T18:06:23.787+0000] {taskinstance.py:1398} INFO - Marking task as FAILED. dag_id=user_etl_dag, task_id=load_users_to_postgres_db, execution_date=20250422T180007, start_date=20250422T180603, end_date=20250422T180623
[2025-04-22T18:06:23.824+0000] {standard_task_runner.py:104} ERROR - Failed to execute job 18 for task load_users_to_postgres_db (connection to server on socket "/var/run/postgresql/.s.PGSQL.5433" failed: No such file or directory
	Is the server running locally and accepting connections on that socket?
; 696)
[2025-04-22T18:06:23.882+0000] {local_task_job_runner.py:228} INFO - Task exited with return code 1
[2025-04-22T18:06:23.939+0000] {taskinstance.py:2776} INFO - 0 downstream tasks scheduled from follow-on schedule check
